2023-06-08 06:23:20,731 INFO    StreamThr :18013 [internal.py:wandb_internal():86] W&B internal server running at pid: 18013, started at: 2023-06-08 06:23:20.731056
2023-06-08 06:23:20,732 DEBUG   HandlerThread:18013 [handler.py:handle_request():144] handle_request: status
2023-06-08 06:23:20,738 INFO    WriterThread:18013 [datastore.py:open_for_write():85] open: /home/modf/wnab-workshop/wandb/run-20230608_062320-n6yts4yq/run-n6yts4yq.wandb
2023-06-08 06:23:20,738 DEBUG   SenderThread:18013 [sender.py:send():369] send: header
2023-06-08 06:23:20,739 DEBUG   SenderThread:18013 [sender.py:send():369] send: run
2023-06-08 06:23:21,405 ERROR   SenderThread:18013 [internal_api.py:execute():323] 404 response executing GraphQL.
2023-06-08 06:23:21,405 ERROR   SenderThread:18013 [internal_api.py:execute():324] {"errors":[{"message":"entity my_wandb_entity not found during upsertBucket","path":["upsertBucket"]}],"data":{"upsertBucket":null}}
2023-06-08 06:23:21,405 ERROR   SenderThread:18013 [sender.py:send_run():955] It appears that you do not have permission to access the requested resource. Please reach out to the project owner to grant you access. If you have the correct permissions, verify that there are no issues with your networking setup.(Error 404: Not Found)
Traceback (most recent call last):
  File "/home/modf/.local/lib/python3.10/site-packages/wandb/sdk/lib/retry.py", line 131, in __call__
    result = self._call_fn(*args, **kwargs)
  File "/home/modf/.local/lib/python3.10/site-packages/wandb/sdk/internal/internal_api.py", line 320, in execute
    return self.client.execute(*args, **kwargs)  # type: ignore
  File "/home/modf/.local/lib/python3.10/site-packages/wandb/vendor/gql-0.2.0/wandb_gql/client.py", line 52, in execute
    result = self._get_result(document, *args, **kwargs)
  File "/home/modf/.local/lib/python3.10/site-packages/wandb/vendor/gql-0.2.0/wandb_gql/client.py", line 60, in _get_result
    return self.transport.execute(document, *args, **kwargs)
  File "/home/modf/.local/lib/python3.10/site-packages/wandb/sdk/lib/gql_request.py", line 56, in execute
    request.raise_for_status()
  File "/usr/lib/python3/dist-packages/requests/models.py", line 943, in raise_for_status
    raise HTTPError(http_error_msg, response=self)
requests.exceptions.HTTPError: 404 Client Error: Not Found for url: https://api.wandb.ai/graphql

During handling of the above exception, another exception occurred:

Traceback (most recent call last):
  File "/home/modf/.local/lib/python3.10/site-packages/wandb/sdk/internal/sender.py", line 953, in send_run
    self._init_run(run, config_value_dict)
  File "/home/modf/.local/lib/python3.10/site-packages/wandb/sdk/internal/sender.py", line 991, in _init_run
    server_run, inserted, server_messages = self._api.upsert_run(
  File "/home/modf/.local/lib/python3.10/site-packages/wandb/apis/normalize.py", line 73, in wrapper
    raise err
  File "/home/modf/.local/lib/python3.10/site-packages/wandb/apis/normalize.py", line 41, in wrapper
    return func(*args, **kwargs)
  File "/home/modf/.local/lib/python3.10/site-packages/wandb/sdk/internal/internal_api.py", line 1727, in upsert_run
    response = self.gql(
  File "/home/modf/.local/lib/python3.10/site-packages/wandb/sdk/internal/internal_api.py", line 292, in gql
    ret = self._retry_gql(
  File "/home/modf/.local/lib/python3.10/site-packages/wandb/sdk/lib/retry.py", line 147, in __call__
    retry_timedelta_triggered = check_retry_fn(e)
  File "/home/modf/.local/lib/python3.10/site-packages/wandb/util.py", line 908, in check_retry_fn
    return fallback_retry_fn(e)
  File "/home/modf/.local/lib/python3.10/site-packages/wandb/util.py", line 850, in no_retry_auth
    raise CommError(
wandb.errors.CommError: It appears that you do not have permission to access the requested resource. Please reach out to the project owner to grant you access. If you have the correct permissions, verify that there are no issues with your networking setup.(Error 404: Not Found)
2023-06-08 06:23:21,679 DEBUG   HandlerThread:18013 [handler.py:handle_request():144] handle_request: shutdown
2023-06-08 06:23:21,679 INFO    HandlerThread:18013 [handler.py:finish():854] shutting down handler
2023-06-08 06:23:21,739 INFO    WriterThread:18013 [datastore.py:close():298] close: /home/modf/wnab-workshop/wandb/run-20230608_062320-n6yts4yq/run-n6yts4yq.wandb
2023-06-08 06:23:22,407 INFO    SenderThread:18013 [sender.py:finish():1526] shutting down sender
